<robot name="pznachi">
  <link name="Base_Link">
    <inertial>
      <origin xyz="-0.044712 -0.085819 -3.1195E-05" rpy="0 0 0" />
      <mass value="3.5167" />
      <inertia
        ixx="0.012401"
        ixy="0.00014279"
        ixz="4.9087E-06"
        iyy="0.013473"
        iyz="1.7125E-05"
        izz="0.015621" />
    </inertial>
    <visual>
      <origin xyz="0 0 0" rpy="0 0 0" />
      <geometry>
        <mesh filename="meshes/Base_Link.STL" />
      </geometry>
      <material name="">
        <color rgba="0.79216 0.81961 0.93333 1" />
      </material>
    </visual>
    <collision>
      <origin xyz="0 0 0" rpy="0 0 0" />
      <geometry>
        <mesh filename="meshes/Base_Link.STL" />
      </geometry>
    </collision>
  </link>
  <link name="Link1">
    <inertial>
      <origin xyz="-0.019704 0.00089628 0.11902" rpy="0 0 0" />
      <mass value="3.2922" />
      <inertia
        ixx="0.022238"
        ixy="-5.8161E-05"
        ixz="-0.0017628"
        iyy="0.01542"
        iyz="-0.00024604"
        izz="0.01508" />
    </inertial>
    <visual>
      <origin xyz="0 0 0" rpy="0 0 0" />
      <geometry>
        <mesh filename="meshes/Link1.STL" />
      </geometry>
      <material name="">
        <color rgba="0.79216 0.81961 0.93333 1" />
      </material>
    </visual>
    <collision>
      <origin
        xyz="0 0 0"
        rpy="0 0 0" />
      <geometry>
        <mesh
          filename="meshes/Link1.STL" />
      </geometry>
    </collision>
  </link>
  <joint
    name="J1"
    type="revolute">
    <origin
      xyz="0 -0.13764 0"
      rpy="1.5708 0.0078414 -4.8014E-19" />
    <parent
      link="Base_Link" />
    <child
      link="Link1" />
    <axis
      xyz="0 0 1" />
    <limit
      effort="0"
      velocity="0" />
  </joint>
  <link
    name="Link2">
    <inertial>
      <origin
        xyz="-0.022938 -0.00078377 0.12952"
        rpy="0 0 0" />
      <mass
        value="3.4347" />
      <inertia
        ixx="0.037509"
        ixy="6.1064E-05"
        ixz="0.00056234"
        iyy="0.030167"
        iyz="-0.00038733"
        izz="0.014052" />
    </inertial>
    <visual>
      <origin
        xyz="0 0 0"
        rpy="0 0 0" />
      <geometry>
        <mesh
          filename="meshes/Link2.STL" />
      </geometry>
      <material
        name="">
        <color
          rgba="0.79216 0.81961 0.93333 1" />
      </material>
    </visual>
    <collision>
      <origin
        xyz="0 0 0"
        rpy="0 0 0" />
      <geometry>
        <mesh
          filename="meshes/Link2.STL" />
      </geometry>
    </collision>
  </link>
  <joint
    name="J2"
    type="revolute">
    <origin
      xyz="0 0 0.20236"
      rpy="0 0 8.3267E-17" />
    <parent
      link="Link1" />
    <child
      link="Link2" />
    <axis
      xyz="0 1 0" />
    <limit
      effort="0"
      velocity="0" />
  </joint>
  <link
    name="Link3">
    <inertial>
      <origin
        xyz="-0.00019106 -0.000236 0.005569"
        rpy="0 0 0" />
      <mass
        value="1.7565" />
      <inertia
        ixx="0.0032287"
        ixy="7.0475E-06"
        ixz="-0.00027822"
        iyy="0.0052787"
        iyz="8.3236E-07"
        izz="0.0045758" />
    </inertial>
    <visual>
      <origin
        xyz="0 0 0"
        rpy="0 0 0" />
      <geometry>
        <mesh
          filename="meshes/Link3.STL" />
      </geometry>
      <material
        name="">
        <color
          rgba="0.79216 0.81961 0.93333 1" />
      </material>
    </visual>
    <collision>
      <origin
        xyz="0 0 0"
        rpy="0 0 0" />
      <geometry>
        <mesh
          filename="meshes/Link3.STL" />
      </geometry>
    </collision>
  </link>
  <joint
    name="J3"
    type="revolute">
    <origin
      xyz="0 0 0.26"
      rpy="0 -0.0069156 3.5505E-08" />
    <parent
      link="Link2" />
    <child
      link="Link3" />
    <axis
      xyz="0 1 0" />
    <limit
      effort="0"
      velocity="0" />
  </joint>
  <link
    name="Link4">
    <inertial>
      <origin
        xyz="0.097971 9.4676E-05 0.0031244"
        rpy="0 0 0" />
      <mass
        value="1.6439" />
      <inertia
        ixx="0.0030774"
        ixy="-1.5251E-05"
        ixz="5.8138E-05"
        iyy="0.0070292"
        iyz="3.7117E-07"
        izz="0.00829" />
    </inertial>
    <visual>
      <origin
        xyz="0 0 0"
        rpy="0 0 0" />
      <geometry>
        <mesh
          filename="meshes/Link4.STL" />
      </geometry>
      <material
        name="">
        <color
          rgba="0.79216 0.81961 0.93333 1" />
      </material>
    </visual>
    <collision>
      <origin
        xyz="0 0 0"
        rpy="0 0 0" />
      <geometry>
        <mesh
          filename="meshes/Link4.STL" />
      </geometry>
    </collision>
  </link>
  <joint
    name="J4"
    type="revolute">
    <origin
      xyz="0.079383 0 0.025"
      rpy="-0.019365 1.4745E-17 6.5226E-16" />
    <parent
      link="Link3" />
    <child
      link="Link4" />
    <axis
      xyz="1 0 0" />
    <limit
      effort="0"
      velocity="0" />
  </joint>
  <link
    name="Link5">
    <inertial>
      <origin
        xyz="0.020403 -0.0026384 -6.1975E-05"
        rpy="0 0 0" />
      <mass
        value="0.32675" />
      <inertia
        ixx="0.00031814"
        ixy="-2.4055E-05"
        ixz="2.2149E-07"
        iyy="0.00034511"
        iyz="6.3733E-07"
        izz="0.00043062" />
    </inertial>
    <visual>
      <origin
        xyz="0 0 0"
        rpy="0 0 0" />
      <geometry>
        <mesh
          filename="meshes/Link5.STL" />
      </geometry>
      <material
        name="">
        <color
          rgba="0.79216 0.81961 0.93333 1" />
      </material>
    </visual>
    <collision>
      <origin
        xyz="0 0 0"
        rpy="0 0 0" />
      <geometry>
        <mesh
          filename="meshes/Link5.STL" />
      </geometry>
    </collision>
  </link>
  <joint
    name="J5"
    type="revolute">
    <origin
      xyz="0.20062 0 0"
      rpy="-6.9389E-18 0.0018264 -1.3849E-15" />
    <parent
      link="Link4" />
    <child
      link="Link5" />
    <axis
      xyz="0 1 0" />
    <limit
      effort="0"
      velocity="0" />
  </joint>
  <link
    name="Link6">
    <inertial>
      <origin
        xyz="0.0072821 -5.8253E-05 -0.00022338"
        rpy="0 0 0" />
      <mass
        value="0.031021" />
      <inertia
        ixx="1.5737E-05"
        ixy="6.2399E-10"
        ixz="1.1782E-09"
        iyy="8.4458E-06"
        iyz="8.8516E-08"
        izz="8.6667E-06" />
    </inertial>
    <visual>
      <origin
        xyz="0 0 0"
        rpy="0 0 0" />
      <geometry>
        <mesh
          filename="meshes/Link6.STL" />
      </geometry>
      <material
        name="">
        <color
          rgba="0.79216 0.81961 0.93333 1" />
      </material>
    </visual>
    <collision>
      <origin
        xyz="0 0 0"
        rpy="0 0 0" />
      <geometry>
        <mesh
          filename="meshes/Link6.STL" />
      </geometry>
    </collision>
  </link>
  <joint
    name="J6"
    type="revolute">
    <origin
      xyz="0.061686 0.0011 0"
      rpy="0.019384 -2.5153E-17 1.8801E-15" />
    <parent
      link="Link5" />
    <child
      link="Link6" />
    <axis
      xyz="1 0 0" />
    <limit
      effort="0"
      velocity="0" />
  </joint>
</robot>
